Workbook

Sheet Discounts
A1: Customer name: | B1: Plastok OÜ
A2: Customer code: | B2: 11438
A4: Article | B4: Discount % | C4: Article Group
A5: SBR
A6: Black Miami | B6: 60 | C6: A1
A7: Zen Star | B7: 65 | C7: A2
A8: Black Miami 50 | B8: 58 | C8: A3
A9: NBR
A10: Satyr Eco | B10: 60 | C10: B1
A11: Satyr Medium | B11: 60 | C11: B2
A12: Satyr Premium | B12: 60 | C12: B3
A13: Satyr 50 | B13: 58 | C13: B4
A14: EPDM
A15: Manticore Eco | B15: 60 | C15: C1
A16: Manticore Medium | B16: 60 | C16: C2
A17: Manticore Premium | B17: 65 | C17: C3
A18: Manticore 50 | B18: 58 | C18: C4
A19: Manticore Aqua | B19: 65 | C19: C5
A20: Manticore Peroxid | B20: 65 | C20: C6
A21: CR
A22: Wendigo Eco | B22: 60 | C22: D1
A23: Wendigo Medium | B23: 58 | C23: D2
A24: Wendigo Premium | B24: 58 | C24: D3
A25: Wendigo 50 | B25: 58 | C25: D4
A26: Para
A27: Typhon Beige | B27: 65 | C27: E1
A28: Typhon Grey | B28: 65 | C28: E1
A29: Centaur Red | B29: 65 | C29: E2
A30: Centaur Black 40 | B30: 65 | C30: E8
A31: Abraline 60 | B31: 65 | C31: E31
A32: Centaur Black 60 | B32: 65 | C32: E9
A33: Red Dragoon | B33: 65 | C33: E5
A34: Typhon Dustsealing | B34: 70 | C34: E18
A35: Food Grade & VMQ
A36: Pegasus SBR | B36: 60 | C36: F1
A37: Pegasus NBR | B37: 60 | C37: F2
A38: Pegasus EPDM | B38: 60 | C38: F3
A39: Pegasus CR | B39: 60 | C39: F4
A40: Viking Translucent | B40: 60 | C40: F5
A41: Viking Red | B41: 60 | C41: F5
...

Sheet SBR
A1: NR/SBR Rubber sheets
A2: Black Miami | H2: Datasheet
A3: Thickness (mm) | B3: Insertion(s) | C3: Insertion type | D3: Width (mtr) | E3: Length (mtr) | F3: Article nr. | G3: Gross sales price per SQM in EUR | H3: Nett price per SQM in EUR
A4: 1 | B4: - | C4: - | D4: 1.4 | E4: 10 | F4: SX70150 1/0 | G4: 8 | H4: =G4*((100-Discounts!$B$6)/100) -> 3.2
A5: 1 | B5: - | C5: - | D5: 1.4 | E5: 20 | F5: SX70150 1/0 | G5: 8 | H5: =G5*((100-Discounts!$B$6)/100) -> 3.2
A6: 1.5 | B6: - | C6: - | D6: 1.4 | E6: 15 | F6: SX70150 1,5/0 | G6: 9.5 | H6: =G6*((100-Discounts!$B$6)/100) -> 3.8
A7: 1.5 | B7: - | C7: - | D7: 1.5 | E7: 15 | F7: SX70150 1,5/0 | G7: 9.5 | H7: =G7*((100-Discounts!$B$6)/100) -> 3.8
A8: 2 | B8: - | C8: - | D8: 1.2 | E8: 10 | F8: SX70150 2/0 | G8: 12 | H8: =G8*((100-Discounts!$B$6)/100) -> 4.8
A9: 2 | B9: - | C9: - | D9: 1.4 | E9: 10 | F9: SX70150 2/0 | G9: 12 | H9: =G9*((100-Discounts!$B$6)/100) -> 4.8
A10: 2 | B10: - | C10: - | D10: 1.4 | E10: 20 | F10: SX70150 2/0 | G10: 12 | H10: =G10*((100-Discounts!$B$6)/100) -> 4.8
A11: 3 | B11: - | C11: - | D11: 1.2 | E11: 10 | F11: SX70150 3/0 | G11: 17.25 | H11: =G11*((100-Discounts!$B$6)/100) -> 6.9
A12: 3 | B12: - | C12: - | D12: 1.4 | E12: 10 | F12: SX70150 3/0 | G12: 17.25 | H12: =G12*((100-Discounts!$B$6)/100) -> 6.9
A13: 3 | B13: - | C13: - | D13: 1.4 | E13: 20 | F13: SX70150 3/0 | G13: 17.25 | H13: =G13*((100-Discounts!$B$6)/100) -> 6.9
A14: 3 | B14: - | C14: - | D14: 1.8 | E14: 10 | F14: SX70150 3/0 | G14: 17.25 | H14: =G14*((100-Discounts!$B$6)/100) -> 6.9
A15: 4 | B15: - | C15: - | D15: 1.2 | E15: 10 | F15: SX70150 4/0 | G15: 22.75 | H15: =G15*((100-Discounts!$B$6)/100) -> 9.1
... A34: 30 | B34: - | C34: - | D34: 1.4 | E34: 5 | F34: SX70150 30/0 | G34: 166.75 | H34: =G34*((100-Discounts!$B$6)/100) -> 66.7
A35: Black Miami with insertion(s) | H35: Datasheet
A36: Thickness (mm) | B36: Insertion(s) | C36: Insertion type | D36: Width (mtr) | E36: Length (mtr) | F36: Article nr. | G36: Gross sales price per SQM in EUR | H36: Nett price per SQM in EUR
A37: 1.5 | B37: 1 | C37: cotton | D37: 1.4 | E37: 15 | F37: SX70151 1,5/1 | G37: 11 | H37: =G37*((100-Discounts!$B$6)/100) -> 4.4
A38: 2 | B38: 1 | C38: cotton | D38: 1.2 | E38: 10 | F38: SX70151 2/1 | G38: 13.5 | H38: =G38*((100-Discounts!$B$6)/100) -> 5.4
A39: 2 | B39: 1 | C39: cotton | D39: 1.4 | E39: 10 | F39: SX70151 2/1 | G39: 13.5 | H39: =G39*((100-Discounts!$B$6)/100) -> 5.4
A40: 3 | B40: 1 | C40: cotton | D40: 1.2 | E40: 10 | F40: SX70151 3/1 | G40: 18.75 | H40: =G40*((100-Discounts!$B$6)/100) -> 7.5
A41: 3 | B41: 1 | C41: cotton | D41: 1.4 | E41: 10 | F41: SX70151 3/1 | G41: 18.75 | H41: =G41*((100-Discounts!$B$6)/100) -> 7.5
A42: 3 | B42: 1 | C42: cotton | D42: 1.5 | E42: 10 | F42: SX70151 3/1 | G42: 18.75 | H42: =G42*((100-Discounts!$B$6)/100) -> 7.5
A43: 3 | B43: 2 | C43: cotton | D43: 1.2 | E43: 10 | F43: SX70152 3/2 | G43: 20.25 | H43: =G43*((100-Discounts!$B$6)/100) -> 8.1
A44: 3 | B44: 2 | C44: cotton | D44: 1.4 | E44: 10 | F44: SX70152 3/2 | G44: 20.25 | H44: =G44*((100-Discounts!$B$6)/100) -> 8.1
A45: 4 | B45: 1 | C45: cotton | D45: 1.2 | E45: 10 | F45: SX70151 4/1 | G45: 24.25 | H45: =G45*((100-Discounts!$B$6)/100) -> 9.7
A46: 4 | B46: 1 | C46: cotton | D46: 1.4 | E46: 10 | F46: SX70151 4/1 | G46: 24.25 | H46: =G46*((100-Discounts!$B$6)/100) -> 9.7
A47: 4 | B47: 2 | C47: cotton | D47: 1.2 | E47: 10 | F47: SX70152 4/2 | G47: 25.75 | H47: =G47*((100-Discounts!$B$6)/100) -> 10.3
A48: 4 | B48: 2 | C48: cotton | D48: 1.4 | E48: 10 | F48: SX70152 4/2 | G48: 25.75 | H48: =G48*((100-Discounts!$B$6)/100) -> 10.3
... A64: 10 | B64: 2 | C64: cotton | D64: 1.4 | E64: 5 | F64: SX70152 10/2 | G64: 58 | H64: =G64*((100-Discounts!$B$6)/100) -> 23.2
A65: Black Miami flat sheets | H65: Datasheet
A66: Thickness (mm) | B66: Insertion(s) | C66: Insertion type | D66: Width (mtr) | E66: Length (mtr) | F66: Article nr. | G66: Gross sales price per SQM in EUR | H66: Nett price per piece in EUR
A67: 10 | B67: - | C67: - | D67: 1 | E67: 1 | F67: SX70150 10/0-1x1 | G67: 56.5 | H67: =G67*((100-Discounts!$B$6)/100) -> 22.6
A68: 15 | B68: - | C68: - | D68: 1 | E68: 1 | F68: SX70150 15/0-1x1 | G68: 83.75 | H68: =G68*((100-Discounts!$B$6)/100) -> 33.5
A69: 20 | B69: - | C69: - | D69: 1 | E69: 1 | F69: SX70150 20/0-1x1 | G69: 111.5 | H69: =G69*((100-Discounts!$B$6)/100) -> 44.6
A70: 20 | B70: - | C70: - | D70: 1.5 | E70: 1 | F70: SX70150 20/0-1,5x1 | G70: 167.25 | H70: =G70*((100-Discounts!$B$6)/100) -> 66.9
A71: 25 | B71: - | C71: - | D71: 1 | E71: 1 | F71: SX70150 25/0-1x1 | G71: 137.5 | H71: =G71*((100-Discounts!$B$6)/100) -> 55
A72: 25 | B72: - | C72: - | D72: 1.5 | E72: 1 | F72: SX70150 25/0-1,5x1 | G72: 206.25 | H72: =G72*((100-Discounts!$B$6)/100) -> 82.5
A73: 30 | B73: - | C73: - | D73: 1 | E73: 1 | F73: SX70150 30/0-1x1 | G73: 171.75 | H73: =G73*((100-Discounts!$B$6)/100) -> 68.7
...

Sheet NBR
A1: NBR Rubber sheets
A2: Satyr Eco | H2: Datasheet
A3: Thickness (mm) | B3: Insertion(s) | C3: Insertion type | D3: Width (mtr) | E3: Length (mtr) | F3: Article nr. | G3: Gross sales price per SQM in EUR | H3: Nett price per SQM in EUR
A4: 1 | B4: - | C4: - | D4: 1.4 | E4: 20 | F4: NB7010 1/0 | G4: 9.75 | H4: =G4*((100-Discounts!$B$10)/100) -> 3.9
A5: 1.5 | B5: - | C5: - | D5: 1.4 | E5: 15 | F5: NB7010 1,5/0 | G5: 13.25 | H5: =G5*((100-Discounts!$B$10)/100) -> 5.3
A6: 2 | B6: - | C6: - | D6: 1.2 | E6: 10 | F6: NB7010 2/0 | G6: 16.25 | H6: =G6*((100-Discounts!$B$10)/100) -> 6.5
A7: 2 | B7: - | C7: - | D7: 1.4 | E7: 10 | F7: NB7010 2/0 | G7: 16.25 | H7: =G7*((100-Discounts!$B$10)/100) -> 6.5
A8: 3 | B8: - | C8: - | D8: 1.2 | E8: 10 | F8: NB7010 3/0 | G8: 23 | H8: =G8*((100-Discounts!$B$10)/100) -> 9.2
A9: 3 | B9: - | C9: - | D9: 1.4 | E9: 10 | F9: NB7010 3/0 | G9: 23 | H9: =G9*((100-Discounts!$B$10)/100) -> 9.2
A10: 4 | B10: - | C10: - | D10: 1.2 | E10: 10 | F10: NB7010 4/0 | G10: 30.5 | H10: =G10*((100-Discounts!$B$10)/100) -> 12.2
A11: 4 | B11: - | C11: - | D11: 1.4 | E11: 10 | F11: NB7010 4/0 | G11: 30.5 | H11: =G11*((100-Discounts!$B$10)/100) -> 12.2
A12: 5 | B12: - | C12: - | D12: 1.2 | E12: 10 | F12: NB7010 5/0 | G12: 38 | H12: =G12*((100-Discounts!$B$10)/100) -> 15.2
A13: 5 | B13: - | C13: - | D13: 1.4 | E13: 10 | F13: NB7010 5/0 | G13: 38 | H13: =G13*((100-Discounts!$B$10)/100) -> 15.2
A14: 6 | B14: - | C14: - | D14: 1.2 | E14: 10 | F14: NB7010 6/0 | G14: 44.5 | H14: =G14*((100-Discounts!$B$10)/100) -> 17.8
A15: 6 | B15: - | C15: - | D15: 1.4 | E15: 10 | F15: NB7010 6/0 | G15: 44.5 | H15: =G15*((100-Discounts!$B$10)/100) -> 17.8
... A29: 25 | B29: - | C29: - | D29: 1.4 | E29: 5 | F29: NB7010 25/0 | G29: 171.75 | H29: =G29*((100-Discounts!$B$10)/100) -> 68.7
A30: Satyr Eco with insertion(s) | H30: Datasheet
A31: Thickness (mm) | B31: Insertion(s) | C31: Insertion type | D31: Width (mtr) | E31: Length (mtr) | F31: Article nr. | G31: Gross sales price per SQM in EUR | H31: Nett price per SQM in EUR
A32: 1.5 | B32: 1 | C32: nylon | D32: 1.4 | E32: 10 | F32: NB7011 1,5/1 | G32: 19.25 | H32: =G32*((100-Discounts!$B$10)/100) -> 7.7
A33: 1.5 | B33: 1 | C33: nylon | D33: 1.4 | E33: 15 | F33: NB7011 1,5/1 | G33: 19.25 | H33: =G33*((100-Discounts!$B$10)/100) -> 7.7
A34: 2 | B34: 1 | C34: nylon | D34: 1.2 | E34: 10 | F34: NB7011 2/1 | G34: 22.25 | H34: =G34*((100-Discounts!$B$10)/100) -> 8.9
A35: 2 | B35: 1 | C35: nylon | D35: 1.4 | E35: 10 | F35: NB7011 2/1 | G35: 22.25 | H35: =G35*((100-Discounts!$B$10)/100) -> 8.9
A36: 3 | B36: 1 | C36: nylon | D36: 1.2 | E36: 10 | F36: NB7011 3/1 | G36: 29 | H36: =G36*((100-Discounts!$B$10)/100) -> 11.6
A37: 3 | B37: 1 | C37: nylon | D37: 1.4 | E37: 10 | F37: NB7011 3/1 | G37: 29 | H37: =G37*((100-Discounts!$B$10)/100) -> 11.6
A38: 3 | B38: 2 | C38: nylon | D38: 1.2 | E38: 10 | F38: NB7012 3/2 | G38: 35 | H38: =G38*((100-Discounts!$B$10)/100) -> 14
A39: 3 | B39: 2 | C39: nylon | D39: 1.4 | E39: 10 | F39: NB7012 3/2 | G39: 35 | H39: =G39*((100-Discounts!$B$10)/100) -> 14
A40: 4 | B40: 1 | C40: nylon | D40: 1.2 | E40: 10 | F40: NB7011 4/1 | G40: 36.5 | H40: =G40*((100-Discounts!$B$10)/100) -> 14.6
A41: 4 | B41: 1 | C41: nylon | D41: 1.4 | E41: 10 | F41: NB7011 4/1 | G41: 36.5 | H41: =G41*((100-Discounts!$B$10)/100) -> 14.6
A42: 4 | B42: 2 | C42: nylon | D42: 1.2 | E42: 10 | F42: NB7012 4/2 | G42: 42.5 | H42: =G42*((100-Discounts!$B$10)/100) -> 17
A43: 4 | B43: 2 | C43: nylon | D43: 1.4 | E43: 10 | F43: NB7012 4/2 | G43: 42.5 | H43: =G43*((100-Discounts!$B$10)/100) -> 17
... A51: 10 | B51: 2 | C51: nylon | D51: 1.4 | E51: 10 | F51: NB7012 10/2 | G51: 83.25 | H51: =G51*((100-Discounts!$B$10)/100) -> 33.3
A52: Satyr Eco flat sheets | H52: Datasheet
A53: Thickness (mm) | B53: Insertion(s) | C53: Insertion type | D53: Width (mtr) | E53: Length (mtr) | F53: Article nr. | G53: Gross sales price per SQM in EUR | H53: Nett price per SQM in EUR
A54: 10 | B54: - | C54: - | D54: 1 | E54: 1 | F54: NB7010 10/0-1x1 | G54: 75 | H54: =G54*((100-Discounts!$B$10)/100) -> 30
A55: 15 | B55: - | C55: - | D55: 1 | E55: 1 | F55: NB7010 15/0-1x1 | G55: 110.25 | H55: =G55*((100-Discounts!$B$10)/100) -> 44.1
A56: 20 | B56: - | C56: - | D56: 1 | E56: 1 | F56: NB7010 20/0-1x1 | G56: 144 | H56: =G56*((100-Discounts!$B$10)/100) -> 57.6
A57: 20 | B57: - | C57: - | D57: 1.4 | E57: 2 | F57: NB7010 20/0 | G57: 137.25 | H57: =G57*((100-Discounts!$B$10)/100) -> 54.9
A58: 20 | B58: - | C58: - | D58: 1.5 | E58: 1 | F58: NB7010 10/0-1,5x1 | G58: 205.875 | H58: =G58*((100-Discounts!$B$10)/100) -> 82.35
A59: 25 | B59: - | C59: - | D59: 1 | E59: 1 | F59: NB7010 25/0-1x1 | G59: 182 | H59: =G59*((100-Discounts!$B$10)/100) -> 72.8
A60: 25 | B60: - | C60: - | D60: 1.5 | E60: 1 | F60: NB7010 25/0-1,5x1 | G60: 273 | H60: =G60*((100-Discounts!$B$10)/100) -> 109.2
...

Sheet EPDM
A1: EPDM Rubber sheets
A2: Manticore Eco | H2: Datasheet
A3: Thickness (mm) | B3: Insertion(s) | C3: Insertion type | D3: Width (mtr) | E3: Length (mtr) | F3: Article nr. | G3: Gross sales price per SQM in EUR | H3: Nett price per SQM in EUR
A4: 1 | B4: - | C4: - | D4: 1.4 | E4: 20 | F4: EP7010 1/0 | G4: 9.75 | H4: =G4*((100-Discounts!$B$15)/100) -> 3.9
A5: 1.5 | B5: - | C5: - | D5: 1.4 | E5: 15 | F5: EP7010 1,5/0 | G5: 13.25 | H5: =G5*((100-Discounts!$B$15)/100) -> 5.3
A6: 2 | B6: - | C6: - | D6: 1.2 | E6: 10 | F6: EP7010 2/0 | G6: 16.25 | H6: =G6*((100-Discounts!$B$15)/100) -> 6.5
A7: 2 | B7: - | C7: - | D7: 1.4 | E7: 10 | F7: EP7010 2/0 | G7: 16.25 | H7: =G7*((100-Discounts!$B$15)/100) -> 6.5
A8: 3 | B8: - | C8: - | D8: 1.2 | E8: 10 | F8: EP7010 3/0 | G8: 23 | H8: =G8*((100-Discounts!$B$15)/100) -> 9.2
A9: 3 | B9: - | C9: - | D9: 1.4 | E9: 10 | F9: EP7010 3/0 | G9: 23 | H9: =G9*((100-Discounts!$B$15)/100) -> 9.2
A10: 4 | B10: - | C10: - | D10: 1.2 | E10: 10 | F10: EP7010 4/0 | G10: 30.5 | H10: =G10*((100-Discounts!$B$15)/100) -> 12.2
A11: 4 | B11: - | C11: - | D11: 1.4 | E11: 10 | F11: EP7010 4/0 | G11: 30.5 | H11: =G11*((100-Discounts!$B$15)/100) -> 12.2
A12: 5 | B12: - | C12: - | D12: 1.2 | E12: 10 | F12: EP7010 5/0 | G12: 38 | H12: =G12*((100-Discounts!$B$15)/100) -> 15.2
A13: 5 | B13: - | C13: - | D13: 1.4 | E13: 10 | F13: EP7010 5/0 | G13: 38 | H13: =G13*((100-Discounts!$B$15)/100) -> 15.2
A14: 6 | B14: - | C14: - | D14: 1.2 | E14: 10 | F14: EP7010 6/0 | G14: 44.5 | H14: =G14*((100-Discounts!$B$15)/100) -> 17.8
A15: 6 | B15: - | C15: - | D15: 1.4 | E15: 10 | F15: EP7010 6/0 | G15: 44.5 | H15: =G15*((100-Discounts!$B$15)/100) -> 17.8
... A29: 25 | B29: - | C29: - | D29: 1.4 | E29: 5 | F29: EP7010 25/0 | G29: 171.75 | H29: =G29*((100-Discounts!$B$15)/100) -> 68.7
A30: Manticore Eco with insertion(s) | H30: Datasheet
A31: Thickness (mm) | B31: Insertion(s) | C31: Insertion type | D31: Width (mtr) | E31: Length (mtr) | F31: Article nr. | G31: Gross sales price per SQM in EUR | H31: Nett price per SQM in EUR
A32: 1.5 | B32: 1 | C32: nylon | D32: 1.4 | E32: 10 | F32: EP7011 1,5/1 | G32: 19.25 | H32: =G32*((100-Discounts!$B$15)/100) -> 7.7
A33: 1.5 | B33: 1 | C33: nylon | D33: 1.4 | E33: 15 | F33: EP7011 1,5/1 | G33: 19.25 | H33: =G33*((100-Discounts!$B$15)/100) -> 7.7
A34: 2 | B34: 1 | C34: nylon | D34: 1.2 | E34: 10 | F34: EP7011 2/1 | G34: 22.25 | H34: =G34*((100-Discounts!$B$15)/100) -> 8.9
A35: 2 | B35: 1 | C35: nylon | D35: 1.4 | E35: 10 | F35: EP7011 2/1 | G35: 22.25 | H35: =G35*((100-Discounts!$B$15)/100) -> 8.9
A36: 3 | B36: 1 | C36: nylon | D36: 1.2 | E36: 10 | F36: EP7011 3/1 | G36: 29 | H36: =G36*((100-Discounts!$B$15)/100) -> 11.6
A37: 3 | B37: 1 | C37: nylon | D37: 1.4 | E37: 10 | F37: EP7011 3/1 | G37: 29 | H37: =G37*((100-Discounts!$B$15)/100) -> 11.6
A38: 3 | B38: 2 | C38: nylon | D38: 1.2 | E38: 10 | F38: EP7012 3/2 | G38: 35 | H38: =G38*((100-Discounts!$B$15)/100) -> 14
A39: 3 | B39: 2 | C39: nylon | D39: 1.4 | E39: 10 | F39: EP7012 3/2 | G39: 35 | H39: =G39*((100-Discounts!$B$15)/100) -> 14
A40: 4 | B40: 1 | C40: nylon | D40: 1.2 | E40: 10 | F40: EP7011 4/1 | G40: 36.5 | H40: =G40*((100-Discounts!$B$15)/100) -> 14.6
A41: 4 | B41: 1 | C41: nylon | D41: 1.4 | E41: 10 | F41: EP7011 4/1 | G41: 36.5 | H41: =G41*((100-Discounts!$B$15)/100) -> 14.6
A42: 4 | B42: 2 | C42: nylon | D42: 1.2 | E42: 10 | F42: EP7012 4/2 | G42: 42.5 | H42: =G42*((100-Discounts!$B$15)/100) -> 17
A43: 4 | B43: 2 | C43: nylon | D43: 1.4 | E43: 10 | F43: EP7012 4/2 | G43: 42.5 | H43: =G43*((100-Discounts!$B$15)/100) -> 17
... A51: 10 | B51: 2 | C51: nylon | D51: 1.4 | E51: 10 | F51: EP7012 10/2 | G51: 83.25 | H51: =G51*((100-Discounts!$B$15)/100) -> 33.3
A52: Manticore Eco flat sheets | H52: Datasheet
A53: Thickness (mm) | B53: Insertion(s) | C53: Insertion type | D53: Width (mtr) | E53: Length (mtr) | F53: Article nr. | G53: Gross sales price per SQM in EUR | H53: Nett price per SQM in EUR
A54: 10 | B54: - | C54: - | D54: 1 | E54: 1 | F54: EP7010 10/0-1x1 | G54: 75 | H54: =G54*((100-Discounts!$B$15)/100) -> 30
A55: 15 | B55: - | C55: - | D55: 1 | E55: 1 | F55: EP7010 15/0-1x1 | G55: 110.25 | H55: =G55*((100-Discounts!$B$15)/100) -> 44.1
A56: 20 | B56: - | C56: - | D56: 1 | E56: 1 | F56: EP7010 20/0-1x1 | G56: 144 | H56: =G56*((100-Discounts!$B$15)/100) -> 57.6
A57: 20 | B57: - | C57: - | D57: 1.4 | E57: 2 | F57: EP7010 20/0 | G57: 137.25 | H57: =G57*((100-Discounts!$B$15)/100) -> 54.9
A58: 20 | B58: - | C58: - | D58: 1.5 | E58: 1 | F58: EP7010 10/0-1,5x1 | G58: 216.25 | H58: =G58*((100-Discounts!$B$15)/100) -> 86.5
A59: 25 | B59: - | C59: - | D59: 1 | E59: 1 | F59: EP7010 25/0-1x1 | G59: 182 | H59: =G59*((100-Discounts!$B$15)/100) -> 72.8
A60: 25 | B60: - | C60: - | D60: 1.5 | E60: 1 | F60: EP7010 25/0-1,5x1 | G60: 273 | H60: =G60*((100-Discounts!$B$15)/100) -> 109.2
...

Sheet CR
A1: CR Rubber sheets
A2: Wendigo Eco | H2: Datasheet
A3: Thickness (mm) | B3: Insertion(s) | C3: Insertion type | D3: Width (mtr) | E3: Length (mtr) | F3: Article nr. | G3: Gross sales price per SQM in EUR | H3: Nett price per SQM in EUR
A4: 1 | B4: - | C4: - | D4: 1.4 | E4: 20 | F4: CR7010 1/0 | G4: 10 | H4: =G4*((100-Discounts!$B$22)/100) -> 4
A5: 1.5 | B5: - | C5: - | D5: 1.4 | E5: 15 | F5: CR7010 1,5/0 | G5: 13.75 | H5: =G5*((100-Discounts!$B$22)/100) -> 5.5
A6: 2 | B6: - | C6: - | D6: 1.2 | E6: 10 | F6: CR7010 2/0 | G6: 16.75 | H6: =G6*((100-Discounts!$B$22)/100) -> 6.7
A7: 2 | B7: - | C7: - | D7: 1.4 | E7: 10 | F7: CR7010 2/0 | G7: 16.75 | H7: =G7*((100-Discounts!$B$22)/100) -> 6.7
A8: 3 | B8: - | C8: - | D8: 1.2 | E8: 10 | F8: CR7010 3/0 | G8: 23.5 | H8: =G8*((100-Discounts!$B$22)/100) -> 9.4
A9: 3 | B9: - | C9: - | D9: 1.4 | E9: 10 | F9: CR7010 3/0 | G9: 23.5 | H9: =G9*((100-Discounts!$B$22)/100) -> 9.4
A10: 4 | B10: - | C10: - | D10: 1.2 | E10: 10 | F10: CR7010 4/0 | G10: 31.5 | H10: =G10*((100-Discounts!$B$22)/100) -> 12.6
A11: 4 | B11: - | C11: - | D11: 1.4 | E11: 10 | F11: CR7010 4/0 | G11: 31.5 | H11: =G11*((100-Discounts!$B$22)/100) -> 12.6
A12: 5 | B12: - | C12: - | D12: 1.2 | E12: 10 | F12: CR7010 5/0 | G12: 39.25 | H12: =G12*((100-Discounts!$B$22)/100) -> 15.7
A13: 5 | B13: - | C13: - | D13: 1.4 | E13: 10 | F13: CR7010 5/0 | G13: 39.25 | H13: =G13*((100-Discounts!$B$22)/100) -> 15.7
A14: 6 | B14: - | C14: - | D14: 1.2 | E14: 10 | F14: CR7010 6/0 | G14: 45.75 | H14: =G14*((100-Discounts!$B$22)/100) -> 18.3
A15: 6 | B15: - | C15: - | D15: 1.4 | E15: 10 | F15: CR7010 6/0 | G15: 45.75 | H15: =G15*((100-Discounts!$B$22)/100) -> 18.3
... A29: 25 | B29: - | C29: - | D29: 1.4 | E29: 5 | F29: CR7010 25/0 | G29: 176.75 | H29: =G29*((100-Discounts!$B$22)/100) -> 70.7
A30: Wendigo Eco with insertion(s) | H30: Datasheet
A31: Thickness (mm) | B31: Insertion(s) | C31: Insertion type | D31: Width (mtr) | E31: Length (mtr) | F31: Article nr. | G31: Gross sales price per SQM in EUR | H31: Nett price per SQM in EUR
A32: 1.5 | B32: 1 | C32: nylon | D32: 1.4 | E32: 10 | F32: CR7011 1,5/1 | G32: 19.75 | H32: =G32*((100-Discounts!$B$22)/100) -> 7.9
A33: 1.5 | B33: 1 | C33: nylon | D33: 1.4 | E33: 15 | F33: CR7011 1,5/1 | G33: 19.75 | H33: =G33*((100-Discounts!$B$22)/100) -> 7.9
A34: 2 | B34: 1 | C34: nylon | D34: 1.2 | E34: 10 | F34: CR7011 2/1 | G34: 22.75 | H34: =G34*((100-Discounts!$B$22)/100) -> 9.1
A35: 2 | B35: 1 | C35: nylon | D35: 1.4 | E35: 10 | F35: CR7011 2/1 | G35: 22.75 | H35: =G35*((100-Discounts!$B$22)/100) -> 9.1
A36: 3 | B36: 1 | C36: nylon | D36: 1.2 | E36: 10 | F36: CR7011 3/1 | G36: 29.5 | H36: =G36*((100-Discounts!$B$22)/100) -> 11.8
A37: 3 | B37: 1 | C37: nylon | D37: 1.4 | E37: 10 | F37: CR7011 3/1 | G37: 29.5 | H37: =G37*((100-Discounts!$B$22)/100) -> 11.8
A38: 3 | B38: 2 | C38: nylon | D38: 1.2 | E38: 10 | F38: CR7012 3/2 | G38: 35.5 | H38: =G38*((100-Discounts!$B$22)/100) -> 14.2
A39: 3 | B39: 2 | C39: nylon | D39: 1.4 | E39: 10 | F39: CR7012 3/2 | G39: 35.5 | H39: =G39*((100-Discounts!$B$22)/100) -> 14.2
A40: 4 | B40: 1 | C40: nylon | D40: 1.2 | E40: 10 | F40: CR7011 4/1 | G40: 37.5 | H40: =G40*((100-Discounts!$B$22)/100) -> 15
A41: 4 | B41: 1 | C41: nylon | D41: 1.4 | E41: 10 | F41: CR7011 4/1 | G41: 37.5 | H41: =G41*((100-Discounts!$B$22)/100) -> 15
A42: 4 | B42: 2 | C42: nylon | D42: 1.2 | E42: 10 | F42: CR7012 4/2 | G42: 43.5 | H42: =G42*((100-Discounts!$B$22)/100) -> 17.4
A43: 4 | B43: 2 | C43: nylon | D43: 1.4 | E43: 10 | F43: CR7012 4/2 | G43: 43.5 | H43: =G43*((100-Discounts!$B$22)/100) -> 17.4
... A51: 10 | B51: 2 | C51: nylon | D51: 1.4 | E51: 10 | F51: CR7012 10/2 | G51: 87.75 | H51: =G51*((100-Discounts!$B$22)/100) -> 35.1
A52: Wendigo Eco flat sheets | H52: Datasheet
A53: Thickness (mm) | B53: Insertion(s) | C53: Insertion type | D53: Width (mtr) | E53: Length (mtr) | F53: Article nr. | G53: Gross sales price per SQM in EUR | H53: Nett price per SQM in EUR
A54: 10 | B54: - | C54: - | D54: 1 | E54: 1 | F54: CR7010 10/0-1x1 | G54: 75.75 | H54: =G54*((100-Discounts!$B$22)/100) -> 30.3
A55: 15 | B55: - | C55: - | D55: 1 | E55: 1 | F55: CR7010 15/0-1x1 | G55: 110.25 | H55: =G55*((100-Discounts!$B$22)/100) -> 44.1
A56: 20 | B56: - | C56: - | D56: 1 | E56: 1 | F56: CR7010 20/0-1x1 | G56: 145.75 | H56: =G56*((100-Discounts!$B$22)/100) -> 58.3
A57: 20 | B57: - | C57: - | D57: 1.4 | E57: 2 | F57: CR7010 20/0 | G57: 141.5 | H57: =G57*((100-Discounts!$B$22)/100) -> 56.6
A58: 20 | B58: - | C58: - | D58: 1.5 | E58: 1 | F58: CR7010 10/0-1,5x1 | G58: 218.75 | H58: =G58*((100-Discounts!$B$22)/100) -> 87.5
A59: 25 | B59: - | C59: - | D59: 1 | E59: 1 | F59: CR7010 25/0-1x1 | G59: 182 | H59: =G59*((100-Discounts!$B$22)/100) -> 72.8
A60: 25 | B60: - | C60: - | D60: 1.5 | E60: 1 | F60: CR7010 25/0-1,5x1 | G60: 273 | H60: =G60*((100-Discounts!$B$22)/100) -> 109.2
...

Sheet Para
A1: Para rubber sheets
A2: Typhon Beige | F2: Datasheet
A3: Thickness (mm) | B3: Width (mtr) | C3: Length (mtr) | D3: Article nr. | E3: Gross sales price per SQM in EUR | F3: Nett price per SQM in EUR
A4: 1 | B4: 1.4 | C4: 20 | D4: AB45110B 1/0 | E4: 19.5 | F4: =E4*((100-Discounts!$B$27)/100) -> 6.825
A5: 1.5 | B5: 1.4 | C5: 15 | D5: AB45110B 1,5/0 | E5: 28 | F5: =E5*((100-Discounts!$B$27)/100) -> 9.8
A6: 2 | B6: 1.4 | C6: 10 | D6: AB45110B 2/0 | E6: 36.25 | F6: =E6*((100-Discounts!$B$27)/100) -> 12.6875
A7: 3 | B7: 1.4 | C7: 10 | D7: AB45110B 3/0 | E7: 53.75 | F7: =E7*((100-Discounts!$B$27)/100) -> 18.8125
A8: 4 | B8: 1.4 | C8: 10 | D8: AB45110B 4/0 | E8: 71.25 | F8: =E8*((100-Discounts!$B$27)/100) -> 24.9375
A9: 5 | B9: 1.4 | C9: 10 | D9: AB45110B 5/0 | E9: 89.25 | F9: =E9*((100-Discounts!$B$27)/100) -> 31.2375
A10: 6 | B10: 1.4 | C10: 10 | D10: AB45110B 6/0 | E10: 105.5 | F10: =E10*((100-Discounts!$B$27)/100) -> 36.925
A11: 8 | B11: 1.4 | C11: 5 | D11: AB45110B 8/0 | E11: 140.5 | F11: =E11*((100-Discounts!$B$27)/100) -> 49.175
A12: 8 | B12: 1.4 | C12: 5 | D12: AB45110B 8/0 | E12: 140.5 | F12: =E12*((100-Discounts!$B$27)/100) -> 49.175
A13: 10 | B13: 1.4 | C13: 5 | D13: AB45110B 10/0 | E13: 172.5 | F13: =E13*((100-Discounts!$B$27)/100) -> 60.375
A14: 10 | B14: 1.4 | C14: 5 | D14: AB45110B 10/0 | E14: 172.5 | F14: =E14*((100-Discounts!$B$27)/100) -> 60.375
A15: 12 | B15: 1.4 | C15: 5 | D15: AB45110B 12/0 | E15: 207 | F15: =E15*((100-Discounts!$B$27)/100) -> 72.45
... A17: 20 | B17: 1.4 | C17: 5 | D17: AB45110B 20/0 | E17: 339.25 | F17: =E17*((100-Discounts!$B$27)/100) -> 118.7375
A18: Typhon Grey | F18: Datasheet
A19: Thickness (mm) | B19: Width (mtr) | C19: Length (mtr) | D19: Article nr. | E19: Gross sales price per SQM in EUR | F19: Nett price per SQM in EUR
A20: 1.5 | B20: 1.4 | C20: 15 | D20: AB45110G 1,5/0 | E20: 28 | F20: =E20*((100-Discounts!$B$28)/100) -> 9.8
A21: 2 | B21: 1.4 | C21: 10 | D21: AB45110G 2/0 | E21: 36.25 | F21: =E21*((100-Discounts!$B$28)/100) -> 12.6875
A22: 3 | B22: 1.4 | C22: 10 | D22: AB45110G 3/0 | E22: 53.75 | F22: =E22*((100-Discounts!$B$28)/100) -> 18.8125
A23: 4 | B23: 1.4 | C23: 10 | D23: AB45110G 4/0 | E23: 71.25 | F23: =E23*((100-Discounts!$B$28)/100) -> 24.9375
A24: 5 | B24: 1.4 | C24: 10 | D24: AB45110G 5/0 | E24: 89.25 | F24: =E24*((100-Discounts!$B$28)/100) -> 31.2375
A25: 6 | B25: 1.4 | C25: 10 | D25: AB45110G 6/0 | E25: 105.5 | F25: =E25*((100-Discounts!$B$28)/100) -> 36.925
A26: 10 | B26: 1.4 | C26: 5 | D26: AB45110G 10/0 | E26: 172.5 | F26: =E26*((100-Discounts!$B$28)/100) -> 60.375
A27: Centaur Red | F27: Datasheet
A28: Thickness (mm) | B28: Width (mtr) | C28: Length (mtr) | D28: Article nr. | E28: Gross sales price per SQM in EUR | F28: Nett price per SQM in EUR
A29: 1 | B29: 1.4 | C29: 20 | D29: AB45110R 1/0 | E29: 13 | F29: =E29*((100-Discounts!$B$29)/100) -> 4.55
A30: 1.5 | B30: 1.4 | C30: 15 | D30: AB45110R 1,5/0 | E30: 19.5 | F30: =E30*((100-Discounts!$B$29)/100) -> 6.825
A31: 2 | B31: 1.4 | C31: 10 | D31: AB45110R 2/0 | E31: 26 | F31: =E31*((100-Discounts!$B$29)/100) -> 9.1
A32: 3 | B32: 1.4 | C32: 10 | D32: AB45110R 3/0 | E32: 40 | F32: =E32*((100-Discounts!$B$29)/100) -> 14
A33: 3 | B33: 2 | C33: 10 | D33: AB45110R 3/0 | E33: 40 | F33: =E33*((100-Discounts!$B$29)/100) -> 14
A34: 4 | B34: 1.4 | C34: 10 | D34: AB45110R 4/0 | E34: 53 | F34: =E34*((100-Discounts!$B$29)/100) -> 18.55
A35: 4 | B35: 2 | C35: 10 | D35: AB45110R 4/0 | E35: 53 | F35: =E35*((100-Discounts!$B$29)/100) -> 18.55
A36: 5 | B36: 1.4 | C36: 10 | D36: AB45110R 5/0 | E36: 65 | F36: =E36*((100-Discounts!$B$29)/100) -> 22.75
A37: 5 | B37: 15 | C37: 10 | D37: AB45110R 5/0 | E37: 65 | F37: =E37*((100-Discounts!$B$29)/100) -> 22.75
A38: 6 | B38: 1.4 | C38: 10 | D38: AB45110R 6/0 | E38: 80 | F38: =E38*((100-Discounts!$B$29)/100) -> 28
A39: 6 | B39: 2 | C39: 10 | D39: AB45110R 6/0 | E39: 80 | F39: =E39*((100-Discounts!$B$29)/100) -> 28
A40: 8 | B40: 1.4 | C40: 10 | D40: AB45110R 8/0 | E40: 105 | F40: =E40*((100-Discounts!$B$29)/100) -> 36.75
... A52: 25 | B52: 2 | C52: 10 | D52: AB45110R 25/0 | E52: 311 | F52: =E52*((100-Discounts!$B$29)/100) -> 108.85
...

Sheet Food Grade & VMQ
A1: Food Grade & VMQ Silicone rubber sheets
A2: Pegasus SBR | F2: Datasheet
A3: Thickness (mm) | B3: Width (mtr) | C3: Length (mtr) | D3: Article nr. | E3: Gross sales price per SQM in EUR | F3: Nett price per SQM in EUR
A4: 1 | B4: 1.4 | C4: 20 | D4: SB60150F 1/0 | E4: 19 | F4: =E4*((100-Discounts!$B$36)/100) -> 7.6
A5: 2 | B5: 1.4 | C5: 10 | D5: SB60150F 2/0 | E5: 33.75 | F5: =E5*((100-Discounts!$B$36)/100) -> 13.5
A6: 3 | B6: 1.4 | C6: 10 | D6: SB60150F 3/0 | E6: 47.25 | F6: =E6*((100-Discounts!$B$36)/100) -> 18.9
A7: 4 | B7: 1.4 | C7: 10 | D7: SB60150F 4/0 | E7: 63 | F7: =E7*((100-Discounts!$B$36)/100) -> 25.2
A8: 5 | B8: 1.4 | C8: 10 | D8: SB60150F 5/0 | E8: 77.5 | F8: =E8*((100-Discounts!$B$36)/100) -> 31
A9: 6 | B9: 1.4 | C9: 10 | D9: SB60150F 6/0 | E9: 92.25 | F9: =E9*((100-Discounts!$B$36)/100) -> 36.9
A10: 8 | B10: 1.4 | C10: 5 | D10: SB60150F 8/0 | E10: 121.75 | F10: =E10*((100-Discounts!$B$36)/100) -> 48.7
A11: 10 | B11: 1.4 | C11: 5 | D11: SB60150F 10/0 | E11: 149.75 | F11: =E11*((100-Discounts!$B$36)/100) -> 59.9
A12: 15 | B12: 1.4 | C12: 5 | D12: SB60150F 15/0 | E12: 220.25 | F12: =E12*((100-Discounts!$B$36)/100) -> 88.1
A13: Pegasus NBR | F13: Datasheet
A14: Thickness (mm) | B14: Width (mtr) | C14: Length (mtr) | D14: Article nr. | E14: Gross sales price per SQM in EUR | F14: Nett price per SQM in EUR
A15: 1 | B15: 1.4 | C15: 20 | D15: NB60140F 1/0 | E15: 20 | F15: =E15*((100-Discounts!$B$37)/100) -> 8
A16: 2 | B16: 1.4 | C16: 10 | D16: NB60140F 2/0 | E16: 35.25 | F16: =E16*((100-Discounts!$B$37)/100) -> 14.1
A17: 3 | B17: 1.4 | C17: 10 | D17: NB60140F 3/0 | E17: 49.75 | F17: =E17*((100-Discounts!$B$37)/100) -> 19.9
A18: 4 | B18: 1.4 | C18: 10 | D18: NB60140F 4/0 | E18: 66.5 | F18: =E18*((100-Discounts!$B$37)/100) -> 26.6
A19: 5 | B19: 1.4 | C19: 10 | D19: NB60140F 5/0 | E19: 81.25 | F19: =E19*((100-Discounts!$B$37)/100) -> 32.5
A20: 6 | B20: 1.4 | C20: 10 | D20: NB60140F 6/0 | E20: 96.75 | F20: =E20*((100-Discounts!$B$37)/100) -> 38.7
A21: 8 | B21: 1.4 | C21: 5 | D21: NB60140F 8/0 | E21: 127.5 | F21: =E21*((100-Discounts!$B$37)/100) -> 51
A22: 10 | B22: 1.4 | C22: 5 | D22: NB60140F 10/0 | E22: 157.75 | F22: =E22*((100-Discounts!$B$37)/100) -> 63.1
A23: Pegasus EPDM | F23: Datasheet
A24: Thickness (mm) | B24: Width (mtr) | C24: Length (mtr) | D24: Article nr. | E24: Gross sales price per SQM in EUR | F24: Nett price per SQM in EUR
A25: 1 | B25: 1.4 | C25: 20 | D25: EP60130F 1/0 | E25: 19.75 | F25: =E25*((100-Discounts!$B$38)/100) -> 7.9
A26: 1.5 | B26: 1.4 | C26: 15 | D26: EP60130F 1,5/0 | E26: 27.75 | F26: =E26*((100-Discounts!$B$38)/100) -> 11.1
A27: 2 | B27: 1.4 | C27: 10 | D27: EP60130F 2/0 | E27: 35.5 | F27: =E27*((100-Discounts!$B$38)/100) -> 14.2
A28: 3 | B28: 1.4 | C28: 10 | D28: EP60130F 3/0 | E28: 50.25 | F28: =E28*((100-Discounts!$B$38)/100) -> 20.1
A29: 4 | B29: 1.4 | C29: 10 | D29: EP60130F 4/0 | E29: 66.5 | F29: =E29*((100-Discounts!$B$38)/100) -> 26.6
A30: 5 | B30: 1.4 | C30: 10 | D30: EP60130F 5/0 | E30: 82.5 | F30: =E30*((100-Discounts!$B$38)/100) -> 33
A31: 6 | B31: 1.4 | C31: 10 | D31: EP60130F 6/0 | E31: 98 | F31: =E31*((100-Discounts!$B$38)/100) -> 39.2
A32: 8 | B32: 1.4 | C32: 5 | D32: EP60130F 8/0 | E32: 129.5 | F32: =E32*((100-Discounts!$B$38)/100) -> 51.8
A33: 10 | B33: 1.4 | C33: 5 | D33: EP60130F 10/0 | E33: 160.75 | F33: =E33*((100-Discounts!$B$38)/100) -> 64.3
A34: Pegasus CR | F34: Datasheet
A35: Thickness (mm) | B35: Width (mtr) | C35: Length (mtr) | D35: Article nr. | E35: Gross sales price per SQM in EUR | F35: Nett price per SQM in EUR
A36: 1 | B36: 1.4 | C36: 10 | D36: NE65145F 1/0 | E36: 35.5 | F36: =E36*((100-Discounts!$B$39)/100) -> 14.2
A37: 2 | B37: 1.4 | C37: 10 | D37: NE65145F 2/0 | E37: 56.5 | F37: =E37*((100-Discounts!$B$39)/100) -> 22.6
A38: 3 | B38: 1.4 | C38: 10 | D38: NE65145F 3/0 | E38: 86.5 | F38: =E38*((100-Discounts!$B$39)/100) -> 34.6
A39: 4 | B39: 1.4 | C39: 10 | D39: NE65145F 4/0 | E39: 115.25 | F39: =E39*((100-Discounts!$B$39)/100) -> 46.1
A40: 5 | B40: 1.4 | C40: 10 | D40: NE65145F 5/0 | E40: 144 | F40: =E40*((100-Discounts!$B$39)/100) -> 57.6
...

Sheet FKM
A1: Fluoro elastomer rubber sheets
A2: Karibu FKM | F2: Datasheet
A3: Thickness (mm) | B3: Width (mtr) | C3: Length (mtr) | D3: Article nr. | E3: Gross sales price per SQM in EUR | F3: Nett price per SQM in EUR
A4: 0.5 | B4: 1.2 | C4: 10 | D4: FPG72190G 0,5/0 | E4: 80 | F4: =E4*((100-Discounts!$B$46)/100) -> 30.4
A5: 1 | B5: 1.2 | C5: 10 | D5: FPG72190G 1/0 | E5: 115 | F5: =E5*((100-Discounts!$B$46)/100) -> 43.7
A6: 1.5 | B6: 1.2 | C6: 10 | D6: FPG72190G 1,5/0 | E6: 170 | F6: =E6*((100-Discounts!$B$46)/100) -> 64.6
A7: 2 | B7: 1.2 | C7: 10 | D7: FPG72190G 2/0 | E7: 220 | F7: =E7*((100-Discounts!$B$46)/100) -> 83.6
A8: 3 | B8: 1.2 | C8: 10 | D8: FPG72190G 3/0 | E8: 330 | F8: =E8*((100-Discounts!$B$46)/100) -> 125.4
A9: 4 | B9: 1.2 | C9: 10 | D9: FPG72190G 4/0 | E9: 440 | F9: =E9*((100-Discounts!$B$46)/100) -> 167.2
A10: 5 | B10: 1.2 | C10: 10 | D10: FPG72190G 5/0 | E10: 550 | F10: =E10*((100-Discounts!$B$46)/100) -> 209
A11: 6 | B11: 1.2 | C11: 10 | D11: FPG72190G 6/0 | E11: 660 | F11: =E11*((100-Discounts!$B$46)/100) -> 250.8
A12: 8 | B12: 1.2 | C12: 5 | D12: FPG72190G 8/0 | E12: 880 | F12: =E12*((100-Discounts!$B$46)/100) -> 334.4
A13: 10 | B13: 1.2 | C13: 5 | D13: FPG72190G 10/0 | E13: 1100 | F13: =E13*((100-Discounts!$B$46)/100) -> 418
A14: 12 | B14: 1.2 | C14: 5 | D14: FPG72190G 12/0 | E14: 1320 | F14: =E14*((100-Discounts!$B$46)/100) -> 501.6

Sheet Various
A1: Various rubber sheets
A2: Kabira Neobenzid | F2: Datasheet
A3: Thickness (mm) | B3: Width (mtr) | C3: Length (mtr) | D3: Article nr. | E3: Gross sales price per SQM in EUR | F3: Nett price per SQM in EUR
A4: 2 | B4: 1.4 | C4: 10 | D4: NB65145G 2/0 | E4: 40 | F4: =E4*((100-Discounts!$B$48)/100) -> 18
A5: 3 | B5: 1.4 | C5: 10 | D5: NB65145G 3/0 | E5: 59.25 | F5: =E5*((100-Discounts!$B$48)/100) -> 26.6625
A6: 4 | B6: 1.4 | C6: 10 | D6: NB65145G 4/0 | E6: 79 | F6: =E6*((100-Discounts!$B$48)/100) -> 35.55
A7: 5 | B7: 1.4 | C7: 10 | D7: NB65145G 5/0 | E7: 98 | F7: =E7*((100-Discounts!$B$48)/100) -> 44.1
A8: 6 | B8: 1.4 | C8: 10 | D8: NB65145G 6/0 | E8: 117.5 | F8: =E8*((100-Discounts!$B$48)/100) -> 52.875
A9: 10 | B9: 1.4 | C9: 5 | D9: NB65145G 10/0 | E9: 194.25 | F9: =E9*((100-Discounts!$B$48)/100) -> 87.4125
A10: Serra CSM | F10: Datasheet
A11: Thickness (mm) | B11: Width (mtr) | C11: Length (mtr) | D11: Article nr. | E11: Gross sales price per SQM in EUR | F11: Nett price per SQM in EUR
A12: 2 | B12: 1.4 | C12: 10 | D12: HN65140 2/0 | E12: 65.5 | F12: =E12*((100-Discounts!$B$49)/100) -> 29.475
A13: 3 | B13: 1.4 | C13: 10 | D13: HN65140 3/0 | E13: 94 | F13: =E13*((100-Discounts!$B$49)/100) -> 42.3
A14: 4 | B14: 1.4 | C14: 10 | D14: HN65140 4/0 | E14: 125.25 | F14: =E14*((100-Discounts!$B$49)/100) -> 56.3625
A15: 5 | B15: 1.4 | C15: 10 | D15: HN65140 5/0 | E15: 155 | F15: =E15*((100-Discounts!$B$49)/100) -> 69.75
A16: 6 | B16: 1.4 | C16: 10 | D16: HN65140 6/0 | E16: 183.75 | F16: =E16*((100-Discounts!$B$49)/100) -> 82.6875
A17: Rama Butyl | F17: Datasheet
A18: Thickness (mm) | B18: Width (mtr) | C18: Length (mtr) | D18: Article nr. | E18: Gross sales price per SQM in EUR | F18: Nett price per SQM in EUR
A19: 2 | B19: 1.4 | C19: 10 | D19: IR60120 2/0 | E19: 47.75 | F19: =E19*((100-Discounts!$B$50)/100) -> 21.4875
A20: 3 | B20: 1.4 | C20: 10 | D20: IR60120 3/0 | E20: 70.5 | F20: =E20*((100-Discounts!$B$50)/100) -> 31.725
A21: 4 | B21: 1.4 | C21: 10 | D21: IR60120 4/0 | E21: 94 | F21: =E21*((100-Discounts!$B$50)/100) -> 42.3
A22: 5 | B22: 1.4 | C22: 10 | D22: IR60120 5/0 | E22: 116.75 | F22: =E22*((100-Discounts!$B$50)/100) -> 52.5375

Sheet Matting
A1: Rubber matting
A2: Cobra | G2: Photo | H2: Datasheet
A3: Thickness (mm) | B3: Insertion(s) | C3: Insertion type | D3: Width (mtr) | E3: Length (mtr) | F3: Article nr. | G3: Gross sales price per SQM in EUR | H3: Nett price per SQM in EUR
A4: 3 | B4: - | C4: - | D4: 1.6 | E4: 10 | F4: SX70150C 3/0 | G4: 18 | H4: =G4*((100-Discounts!$B$52)/100) -> 8.1
A5: 3 | B5: - | C5: - | D5: 1.7 | E5: 10 | F5: SX70150C 3/0 | G5: 18 | H5: =G5*((100-Discounts!$B$52)/100) -> 8.1
A6: 3 | B6: - | C6: - | D6: 1.8 | E6: 10 | F6: SX70150C 3/0 | G6: 18 | H6: =G6*((100-Discounts!$B$52)/100) -> 8.1
A7: 3 | B7: - | C7: - | D7: 2 | E7: 10 | F7: SX70150C 3/0 | G7: 18 | H7: =G7*((100-Discounts!$B$52)/100) -> 8.1
A8: 4 | B8: 2 | C8: nylon | D8: 2 | E8: 10 | F8: SX70150C 4/2 | G8: 34.5 | H8: =G8*((100-Discounts!$B$52)/100) -> 15.525
A9: 5 | B9: - | C9: - | D9: 2 | E9: 10 | F9: SX70150C 5/0 | G9: 29.25 | H9: =G9*((100-Discounts!$B$52)/100) -> 13.1625
A10: 6 | B10: 2 | C10: nylon | D10: 1.45 | E10: 12 | F10: SX70150C 6/2 | G10: 44 | H10: =G10*((100-Discounts!$B$52)/100) -> 19.8
A11: 6 | B11: 2 | C11: nylon | D11: 1.7 | E11: 12 | F11: SX70150C 6/2 | G11: 44 | H11: =G11*((100-Discounts!$B$52)/100) -> 19.8
A12: 6 | B12: 2 | C12: nylon | D12: 2 | E12: 20 | F12: SX70150C 6/2 | G12: 44 | H12: =G12*((100-Discounts!$B$52)/100) -> 19.8
A13: 8 | B13: 1 | C13: nylon | D13: 1.7 | E13: 12 | F13: SX70150C 8/1 | G13: 50 | H13: =G13*((100-Discounts!$B$52)/100) -> 22.5
A14: 8 | B14: 1 | C14: nylon | D14: 2 | E14: 10 | F14: SX70150C 8/1 | G14: 50 | H14: =G14*((100-Discounts!$B$52)/100) -> 22.5
A15: Feniks Insulation Fine Rib Mat | G15: Photo | H15: Datasheet
A16: Thickness (mm) | B16: Insertion(s) | C16: Insertion type | D16: Width (mtr) | E16: Length (mtr) | F16: Article nr. | G16: Gross sales price per SQM in EUR | H16: Nett price per SQM in EUR | I16: Class | J16: Colour | K16: Proof Test Voltage | L16: Resistance | M16: Maximum use voltage
A17: 3 | B17: - | C17: - | D17: 1 | E17: 10 | F17: ELS30000G 3/0 | G17: 38 | H17: =G17*((100-Discounts!$B$53)/100) -> 15.2 | I17: 2 | J17: Grey | K17: 20 kV | L17: 30 kV | M17: 17 kV
A18: 3 | B18: - | C18: - | D18: 1.2 | E18: 10 | F18: ELS30000G 3/0 | G18: 38 | H18: =G18*((100-Discounts!$B$53)/100) -> 15.2 | I18: 2 | J18: Grey | K18: 20 kV | L18: 30 kV | M18: 17 kV
A19: 3 | B19: - | C19: - | D19: 1 | E19: 10 | F19: ELS30000G 3/0 | G19: 38 | H19: =G19*((100-Discounts!$B$53)/100) -> 15.2 | I19: 2 | J19: Black | K19: 20 kV | L19: 30 kV | M19: 17 kV
A20: 4.5 | B20: - | C20: - | D20: 1 | E20: 10 | F20: ELS50000G 4,5/0 | G20: 58.5 | H20: =G20*((100-Discounts!$B$53)/100) -> 23.4 | I20: 4 | J20: Grey | K20: 40 kV | L20: 50 kV | M20: 36 kV
A21: 4.5 | B21: - | C21: - | D21: 1.2 | E21: 10 | F21: ELS50000G 4,5/0 | G21: 58.5 | H21: =G21*((100-Discounts!$B$53)/100) -> 23.4 | I21: 4 | J21: Grey | K21: 40 kV | L21: 50 kV | M21: 36 kV
A22: Feniks Isocarpet | G22: Photo | H22: Datasheet
A23: Thickness (mm) | B23: Insertion(s) | C23: Insertion type | D23: Width (mtr) | E23: Length (mtr) | F23: Article nr. | G23: Gross sales price per SQM in EUR | H23: Nett price per SQM in EUR | I23: Class | J23: Colour | K23: Proof Test Voltage | L23: Resistance | M23: Maximum use voltage
A24: 1.6 | B24: - | C24: - | D24: 1 | E24: 10 | F24: ELS1000V 1,6/0 | G24: 27 | H24: =G24*((100-Discounts!$B$53)/100) -> 10.8 | I24: 0 | J24: Orange | K24: 5 kV | L24: 10 kV | M24: 1 kV
A25: Feniks Insulation Checker Mat | G25: Photo | H25: Datasheet
A26: Thickness (mm) | B26: Insertion(s) | C26: Insertion type | D26: Width (mtr) | E26: Length (mtr) | F26: Article nr. | G26: Gross sales price per SQM in EUR | H26: Nett price per SQM in EUR | I26: Class | J26: Colour | K26: Proof Test Voltage | L26: Resistance | M26: Maximum use voltage
A27: 3 | B27: - | C27: - | D27: 1.4 | E27: 10 | F27: CD65ELSG 3/0 | G27: 40 | H27: =G27*((100-Discounts!$B$53)/100) -> 16 | I27: 2 | J27: Grey | K27: 20 kV | L27: 30 kV | M27: 17 kV
A28: Saturn Fine Rib | G28: Photo | H28: Datasheet
A29: Thickness (mm) | B29: Insertion(s) | C29: Insertion type | D29: Width (mtr) | E29: Length (mtr) | F29: Article nr. | G29: Gross sales price per SQM in EUR | H29: Nett price per SQM in EUR
A30: 3 | B30: - | C30: - | D30: 1 | E30: 10 | F30: MR65 3/0 | G30: 16 | H30: =G30*((100-Discounts!$B$54)/100) -> 6.4
A31: 3 | B31: - | C31: - | D31: 1.2 | E31: 10 | F31: MR65 3/0 | G31: 16 | H31: =G31*((100-Discounts!$B$54)/100) -> 6.4
A32: 3 | B32: - | C32: - | D32: 1.4 | E32: 10 | F32: MR65 3/0 | G32: 16 | H32: =G32*((100-Discounts!$B$54)/100) -> 6.4
A33: 3 | B33: 1 | C33: cotton | D33: 1 | E33: 10 | F33: MR65 3/1 | G33: 17.5 | H33: =G33*((100-Discounts!$B$54)/100) -> 7
A34: 3 | B34: 1 | C34: cotton | D34: 1.2 | E34: 10 | F34: MR65 3/1 | G34: 17.5 | H34: =G34*((100-Discounts!$B$54)/100) -> 7
A35: 4 | B35: - | C35: - | D35: 1 | E35: 10 | F35: MR65 4/0 | G35: 22.75 | H35: =G35*((100-Discounts!$B$54)/100) -> 9.1
A36: 4 | B36: - | C36: - | D36: 1.2 | E36: 10 | F36: MR65 4/0 | G36: 22.75 | H36: =G36*((100-Discounts!$B$54)/100) -> 9.1
A37: Saturn Fine Rib Grey | G37: Photo | H37: Datasheet
A38: Thickness (mm) | B38: Insertion(s) | C38: Insertion type | D38: Width (mtr) | E38: Length (mtr) | F38: Article nr. | G38: Gross sales price per SQM in EUR | H38: Nett price per SQM in EUR
A39: 3 | B39: - | C39: - | D39: 1 | E39: 10 | F39: MR65G 3/0 | G39: 24.25 | H39: =G39*((100-Discounts!$B$54)/100) -> 9.7
A40: 3 | B40: - | C40: - | D40: 1.2 | E40: 10 | F40: MR65G 3/0 | G40: 24.25 | H40: =G40*((100-Discounts!$B$54)/100) -> 9.7
...

Sheet ALL
A1: Article nr. | B1: Name | C1: Gross price, EUR | D1: Quantity | E1: Unit | F1: Thickness | G1: Width | H1: Length | I1: Group | J1: Material | K1: Min °C | L1: Max °C | M1: Colour | N1: Hardness | O1: Insertion | P1: Insertion type | Q1: Nett price, EUR | R1: Catalog | S1: Tensile strength, Mpa | T1: Elongation, % | W1: =-1+SUBTOTAL(103,R:R) -> 862
F2: NR/SBR Rubber sheets | R2: =IF(ISNUMBER(Table3[[#This Row],[Thickness]]), "Zenith", "")
F3: Black Miami | Q3: Datasheet | R3: =IF(ISNUMBER(Table3[[#This Row],[Thickness]]), "Zenith", "")
A4: Article nr. | C4: Gross sales price per SQM in EUR | F4: Thickness (mm) | O4: Insertion(s) | P4: Insertion type | Q4: Nett price per SQM in EUR | R4: =IF(ISNUMBER(Table3[[#This Row],[Thickness]]), "Zenith", "")
A5: SX70150 1/0 | B5: Black Miami | C5: 8 | E5: M2 | F5: 1 | G5: 1400 | H5: 10000 | I5: KUMM | J5: SBR | K5: -30 | L5: 70 | M5: Black | N5: 70 | O5: - | P5: - | Q5: =C5*((100-Discounts!$B$6)/100) -> 3.2 | R5: =IF(ISNUMBER(Table3[[#This Row],[Thickness]]), "Zenith", "") -> Zenith | S5: 3 | T5: 200
A6: SX70150 1/0 | B6: Black Miami | C6: 8 | E6: M2 | F6: 1 | G6: 1400 | H6: 20000 | I6: KUMM | J6: SBR | K6: -30 | L6: 70 | M6: Black | N6: 70 | O6: - | P6: - | Q6: =C6*((100-Discounts!$B$6)/100) -> 3.2 | R6: =IF(ISNUMBER(Table3[[#This Row],[Thickness]]), "Zenith", "") -> Zenith | S6: 3 | T6: 200
A7: SX70150 1,5/0 | B7: Black Miami | C7: 9.5 | E7: M2 | F7: 1.5 | G7: 1400 | H7: 15000 | I7: KUMM | J7: SBR | K7: -30 | L7: 70 | M7: Black | N7: 70 | O7: - | P7: - | Q7: =C7*((100-Discounts!$B$6)/100) -> 3.8 | R7: =IF(ISNUMBER(Table3[[#This Row],[Thickness]]), "Zenith", "") -> Zenith | S7: 3 | T7: 200
A8: SX70150 1,5/0 | B8: Black Miami | C8: 9.5 | E8: M2 | F8: 1.5 | G8: 1500 | H8: 15000 | I8: KUMM | J8: SBR | K8: -30 | L8: 70 | M8: Black | N8: 70 | O8: - | P8: - | Q8: =C8*((100-Discounts!$B$6)/100) -> 3.8 | R8: =IF(ISNUMBER(Table3[[#This Row],[Thickness]]), "Zenith", "") -> Zenith | S8: 3 | T8: 200
A9: SX70150 2/0 | B9: Black Miami | C9: 12 | E9: M2 | F9: 2 | G9: 1200 | H9: 10000 | I9: KUMM | J9: SBR | K9: -30 | L9: 70 | M9: Black | N9: 70 | O9: - | P9: - | Q9: =C9*((100-Discounts!$B$6)/100) -> 4.8 | R9: =IF(ISNUMBER(Table3[[#This Row],[Thickness]]), "Zenith", "") -> Zenith | S9: 3 | T9: 200
A10: SX70150 2/0 | B10: Black Miami | C10: 12 | E10: M2 | F10: 2 | G10: 1400 | H10: 10000 | I10: KUMM | J10: SBR | K10: -30 | L10: 70 | M10: Black | N10: 70 | O10: - | P10: - | Q10: =C10*((100-Discounts!$B$6)/100) -> 4.8 | R10: =IF(ISNUMBER(Table3[[#This Row],[Thickness]]), "Zenith", "") -> Zenith | S10: 3 | T10: 200
A11: SX70150 2/0 | B11: Black Miami | C11: 12 | E11: M2 | F11: 2 | G11: 1400 | H11: 20000 | I11: KUMM | J11: SBR | K11: -30 | L11: 70 | M11: Black | N11: 70 | O11: - | P11: - | Q11: =C11*((100-Discounts!$B$6)/100) -> 4.8 | R11: =IF(ISNUMBER(Table3[[#This Row],[Thickness]]), "Zenith", "") -> Zenith | S11: 3 | T11: 200
A12: SX70150 3/0 | B12: Black Miami | C12: 17.25 | E12: M2 | F12: 3 | G12: 1200 | H12: 10000 | I12: KUMM | J12: SBR | K12: -30 | L12: 70 | M12: Black | N12: 70 | O12: - | P12: - | Q12: =C12*((100-Discounts!$B$6)/100) -> 6.9 | R12: =IF(ISNUMBER(Table3[[#This Row],[Thickness]]), "Zenith", "") -> Zenith | S12: 3 | T12: 200
A13: SX70150 3/0 | B13: Black Miami | C13: 17.25 | E13: M2 | F13: 3 | G13: 1400 | H13: 10000 | I13: KUMM | J13: SBR | K13: -30 | L13: 70 | M13: Black | N13: 70 | O13: - | P13: - | Q13: =C13*((100-Discounts!$B$6)/100) -> 6.9 | R13: =IF(ISNUMBER(Table3[[#This Row],[Thickness]]), "Zenith", "") -> Zenith | S13: 3 | T13: 200
A14: SX70150 3/0 | B14: Black Miami | C14: 17.25 | E14: M2 | F14: 3 | G14: 1400 | H14: 20000 | I14: KUMM | J14: SBR | K14: -30 | L14: 70 | M14: Black | N14: 70 | O14: - | P14: - | Q14: =C14*((100-Discounts!$B$6)/100) -> 6.9 | R14: =IF(ISNUMBER(Table3[[#This Row],[Thickness]]), "Zenith", "") -> Zenith | S14: 3 | T14: 200
A15: SX70150 3/0 | B15: Black Miami | C15: 17.25 | E15: M2 | F15: 3 | G15: 1800 | H15: 10000 | I15: KUMM | J15: SBR | K15: -30 | L15: 70 | M15: Black | N15: 70 | O15: - | P15: - | Q15: =C15*((100-Discounts!$B$6)/100) -> 6.9 | R15: =IF(ISNUMBER(Table3[[#This Row],[Thickness]]), "Zenith", "") -> Zenith | S15: 3 | T15: 200
A16: SX70150 4/0 | B16: Black Miami | C16: 22.75 | E16: M2 | F16: 4 | G16: 1200 | H16: 10000 | I16: KUMM | J16: SBR | K16: -30 | L16: 70 | M16: Black | N16: 70 | O16: - | P16: - | Q16: =C16*((100-Discounts!$B$6)/100) -> 9.1 | R16: =IF(ISNUMBER(Table3[[#This Row],[Thickness]]), "Zenith", "") -> Zenith | S16: 3 | T16: 200
... A35: SX70150 30/0 | B35: Black Miami | C35: 166.75 | E35: M2 | F35: 30 | G35: 1400 | H35: 5000 | I35: KUMM | J35: SBR | K35: -30 | L35: 70 | M35: Black | N35: 70 | O35: - | P35: - | Q35: =C35*((100-Discounts!$B$6)/100) -> 66.7 | R35: =IF(ISNUMBER(Table3[[#This Row],[Thickness]]), "Zenith", "") -> Zenith | S35: 3 | T35: 200
F36: Black Miami with insertion(s) | G36: 0 | H36: 0 | I36: KUMM | J36: SBR | K36: -30 | L36: 70 | M36: Black | N36: 70 | Q36: Datasheet | R36: =IF(ISNUMBER(Table3[[#This Row],[Thickness]]), "Zenith", "")
A37: Article nr. | C37: Gross sales price per SQM in EUR | F37: Thickness (mm) | G37: #VALUE! | H37: #VALUE! | I37: KUMM | J37: SBR | K37: -30 | L37: 70 | M37: Black | N37: 70 | O37: Insertion(s) | P37: Insertion type | Q37: Nett price per SQM in EUR | R37: =IF(ISNUMBER(Table3[[#This Row],[Thickness]]), "Zenith", "")
A38: SX70151 1,5/1 | B38: Black Miami with insertion | C38: 11 | E38: M2 | F38: 1.5 | G38: 1400 | H38: 15000 | I38: KUMM | J38: SBR | K38: -30 | L38: 70 | M38: Black | N38: 70 | O38: 1 | P38: cotton | Q38: =C38*((100-Discounts!$B$6)/100) -> 4.4 | R38: =IF(ISNUMBER(Table3[[#This Row],[Thickness]]), "Zenith", "") -> Zenith | S38: 3 | T38: 200
A39: SX70151 2/1 | B39: Black Miami with insertion | C39: 13.5 | E39: M2 | F39: 2 | G39: 1200 | H39: 10000 | I39: KUMM | J39: SBR | K39: -30 | L39: 70 | M39: Black | N39: 70 | O39: 1 | P39: cotton | Q39: =C39*((100-Discounts!$B$6)/100) -> 5.4 | R39: =IF(ISNUMBER(Table3[[#This Row],[Thickness]]), "Zenith", "") -> Zenith | S39: 3 | T39: 200
A40: SX70151 2/1 | B40: Black Miami with insertion | C40: 13.5 | E40: M2 | F40: 2 | G40: 1400 | H40: 10000 | I40: KUMM | J40: SBR | K40: -30 | L40: 70 | M40: Black | N40: 70 | O40: 1 | P40: cotton | Q40: =C40*((100-Discounts!$B$6)/100) -> 5.4 | R40: =IF(ISNUMBER(Table3[[#This Row],[Thickness]]), "Zenith", "") -> Zenith | S40: 3 | T40: 200
A41: SX70151 3/1 | B41: Black Miami with insertion | C41: 18.75 | E41: M2 | F41: 3 | G41: 1200 | H41: 10000 | I41: KUMM | J41: SBR | K41: -30 | L41: 70 | M41: Black | N41: 70 | O41: 1 | P41: cotton | Q41: =C41*((100-Discounts!$B$6)/100) -> 7.5 | R41: =IF(ISNUMBER(Table3[[#This Row],[Thickness]]), "Zenith", "") -> Zenith | S41: 3 | T41: 200
A42: SX70151 3/1 | B42: Black Miami with insertion | C42: 18.75 | E42: M2 | F42: 3 | G42: 1400 | H42: 10000 | I42: KUMM | J42: SBR | K42: -30 | L42: 70 | M42: Black | N42: 70 | O42: 1 | P42: cotton | Q42: =C42*((100-Discounts!$B$6)/100) -> 7.5 | R42: =IF(ISNUMBER(Table3[[#This Row],[Thickness]]), "Zenith", "") -> Zenith | S42: 3 | T42: 200
A43: SX70151 3/1 | B43: Black Miami with insertion | C43: 18.75 | E43: M2 | F43: 3 | G43: 1500 | H43: 10000 | I43: KUMM | J43: SBR | K43: -30 | L43: 70 | M43: Black | N43: 70 | O43: 1 | P43: cotton | Q43: =C43*((100-Discounts!$B$6)/100) -> 7.5 | R43: =IF(ISNUMBER(Table3[[#This Row],[Thickness]]), "Zenith", "") -> Zenith | S43: 3 | T43: 200
A44: SX70152 3/2 | B44: Black Miami with insertion | C44: 20.25 | E44: M2 | F44: 3 | G44: 1200 | H44: 10000 | I44: KUMM | J44: SBR | K44: -30 | L44: 70 | M44: Black | N44: 70 | O44: 2 | P44: cotton | Q44: =C44*((100-Discounts!$B$6)/100) -> 8.1 | R44: =IF(ISNUMBER(Table3[[#This Row],[Thickness]]), "Zenith", "") -> Zenith | S44: 3 | T44: 200
A45: SX70152 3/2 | B45: Black Miami with insertion | C45: 20.25 | E45: M2 | F45: 3 | G45: 1400 | H45: 10000 | I45: KUMM | J45: SBR | K45: -30 | L45: 70 | M45: Black | N45: 70 | O45: 2 | P45: cotton | Q45: =C45*((100-Discounts!$B$6)/100) -> 8.1 | R45: =IF(ISNUMBER(Table3[[#This Row],[Thickness]]), "Zenith", "") -> Zenith | S45: 3 | T45: 200
A46: SX70151 4/1 | B46: Black Miami with insertion | C46: 24.25 | E46: M2 | F46: 4 | G46: 1200 | H46: 10000 | I46: KUMM | J46: SBR | K46: -30 | L46: 70 | M46: Black | N46: 70 | O46: 1 | P46: cotton | Q46: =C46*((100-Discounts!$B$6)/100) -> 9.7 | R46: =IF(ISNUMBER(Table3[[#This Row],[Thickness]]), "Zenith", "") -> Zenith | S46: 3 | T46: 200
A47: SX70151 4/1 | B47: Black Miami with insertion | C47: 24.25 | E47: M2 | F47: 4 | G47: 1400 | H47: 10000 | I47: KUMM | J47: SBR | K47: -30 | L47: 70 | M47: Black | N47: 70 | O47: 1 | P47: cotton | Q47: =C47*((100-Discounts!$B$6)/100) -> 9.7 | R47: =IF(ISNUMBER(Table3[[#This Row],[Thickness]]), "Zenith", "") -> Zenith | S47: 3 | T47: 200
A48: SX70152 4/2 | B48: Black Miami with insertion | C48: 25.75 | E48: M2 | F48: 4 | G48: 1200 | H48: 10000 | I48: KUMM | J48: SBR | K48: -30 | L48: 70 | M48: Black | N48: 70 | O48: 2 | P48: cotton | Q48: =C48*((100-Discounts!$B$6)/100) -> 10.3 | R48: =IF(ISNUMBER(Table3[[#This Row],[Thickness]]), "Zenith", "") -> Zenith | S48: 3 | T48: 200
A49: SX70152 4/2 | B49: Black Miami with insertion | C49: 25.75 | E49: M2 | F49: 4 | G49: 1400 | H49: 10000 | I49: KUMM | J49: SBR | K49: -30 | L49: 70 | M49: Black | N49: 70 | O49: 2 | P49: cotton | Q49: =C49*((100-Discounts!$B$6)/100) -> 10.3 | R49: =IF(ISNUMBER(Table3[[#This Row],[Thickness]]), "Zenith", "") -> Zenith | S49: 3 | T49: 200
... A65: SX70152 10/2 | B65: Black Miami with insertion | C65: 58 | E65: M2 | F65: 10 | G65: 1400 | H65: 5000 | I65: KUMM | J65: SBR | K65: -30 | L65: 70 | M65: Black | N65: 70 | O65: 2 | P65: cotton | Q65: =C65*((100-Discounts!$B$6)/100) -> 23.2 | R65: =IF(ISNUMBER(Table3[[#This Row],[Thickness]]), "Zenith", "") -> Zenith | S65: 3 | T65: 200
F66: Black Miami flat sheets | G66: 0 | H66: 0 | I66: KUMM | J66: SBR | K66: -30 | L66: 70 | M66: Black | N66: 70 | Q66: Datasheet | R66: =IF(ISNUMBER(Table3[[#This Row],[Thickness]]), "Zenith", "")
A67: Article nr. | C67: Gross sales price per SQM in EUR | F67: Thickness (mm) | G67: #VALUE! | H67: #VALUE! | I67: KUMM | J67: SBR | K67: -30 | L67: 70 | M67: Black | N67: 70 | O67: Insertion(s) | P67: Insertion type | Q67: Nett price per piece in EUR | R67: =IF(ISNUMBER(Table3[[#This Row],[Thickness]]), "Zenith", "")
A68: SX70150 10/0-1x1 | B68: Black Miami flat sheets | C68: 56.5 | E68: M2 | F68: 10 | G68: 1000 | H68: 1000 | I68: KUMM | J68: SBR | K68: -30 | L68: 70 | M68: Black | N68: 70 | O68: - | P68: - | Q68: =C68*((100-Discounts!$B$6)/100) -> 22.6 | R68: =IF(ISNUMBER(Table3[[#This Row],[Thickness]]), "Zenith", "") -> Zenith | S68: 3 | T68: 200
A69: SX70150 15/0-1x1 | B69: Black Miami flat sheets | C69: 83.75 | E69: M2 | F69: 15 | G69: 1000 | H69: 1000 | I69: KUMM | J69: SBR | K69: -30 | L69: 70 | M69: Black | N69: 70 | O69: - | P69: - | Q69: =C69*((100-Discounts!$B$6)/100) -> 33.5 | R69: =IF(ISNUMBER(Table3[[#This Row],[Thickness]]), "Zenith", "") -> Zenith | S69: 3 | T69: 200
A70: SX70150 20/0-1x1 | B70: Black Miami flat sheets | C70: 111.5 | E70: M2 | F70: 20 | G70: 1000 | H70: 1000 | I70: KUMM | J70: SBR | K70: -30 | L70: 70 | M70: Black | N70: 70 | O70: - | P70: - | Q70: =C70*((100-Discounts!$B$6)/100) -> 44.6 | R70: =IF(ISNUMBER(Table3[[#This Row],[Thickness]]), "Zenith", "") -> Zenith | S70: 3 | T70: 200
A71: SX70150 20/0-1,5x1 | B71: Black Miami flat sheets | C71: 167.25 | E71: M2 | F71: 20 | G71: 1500 | H71: 1000 | I71: KUMM | J71: SBR | K71: -30 | L71: 70 | M71: Black | N71: 70 | O71: - | P71: - | Q71: =C71*((100-Discounts!$B$6)/100) -> 66.9 | R71: =IF(ISNUMBER(Table3[[#This Row],[Thickness]]), "Zenith", "") -> Zenith | S71: 3 | T71: 200
A72: SX70150 25/0-1x1 | B72: Black Miami flat sheets | C72: 137.5 | E72: M2 | F72: 25 | G72: 1000 | H72: 1000 | I72: KUMM | J72: SBR | K72: -30 | L72: 70 | M72: Black | N72: 70 | O72: - | P72: - | Q72: =C72*((100-Discounts!$B$6)/100) -> 55 | R72: =IF(ISNUMBER(Table3[[#This Row],[Thickness]]), "Zenith", "") -> Zenith | S72: 3 | T72: 200
A73: SX70150 25/0-1,5x1 | B73: Black Miami flat sheets | C73: 206.25 | E73: M2 | F73: 25 | G73: 1500 | H73: 1000 | I73: KUMM | J73: SBR | K73: -30 | L73: 70 | M73: Black | N73: 70 | O73: - | P73: - | Q73: =C73*((100-Discounts!$B$6)/100) -> 82.5 | R73: =IF(ISNUMBER(Table3[[#This Row],[Thickness]]), "Zenith", "") -> Zenith | S73: 3 | T73: 200
...
